Workbook

Sheet Capa
B2: Capacitação Ciência de Dados — Asimov Jr
B3: Semana 9 — Excel Avançado: Power Query
B5: Dataset: Vendas de uma Loja de Eletrônicos (2023–2024) — mesma base da Semana 8
B6: Desta vez recebida em formato bruto/sujo, simulando uma exportação real de sistema legado.
B9: Estrutura da pasta de trabalho:
B10: • Base_Bruta | C10: Exportação bruta (434 linhas), com cabeçalhos inconsistentes, texto sujo, duplicatas, nulos e erros de digitação.
B11: • Power_Query_ETL | C11: Passo a passo da importação/tratamento no Power Query, incluindo o código M completo (pronto para colar no Editor Avançado).
B12: • Base_Tratada | C12: Resultado do carregamento do Power Query (411 linhas limpas) — Fechar e Carregar como Tabela.
B13: • Medidas_Indicadores | C13: Indicadores construídos como medidas nomeadas + buscas avançadas com múltiplos critérios.
B14: • Tabela_Dinamica | C14: Tabela dinâmica estruturada (Categoria x Canal) com totais, construída sobre a Base_Tratada.
B15: • Dashboard | C15: Mini dashboard analítico com cartões de indicadores e gráficos.
B18: Autor: Mazzer | UNIFEI — Asimov Jr Data Science

Sheet Base_Bruta
A1: id_venda | B1: DATA_VENDA | C1: regiao | D1: categoria | E1: Produto | F1: CANAL | G1: segmento | H1: Cliente | I1: QTD | J1: preco_unitario | K1: custo_unitario | L1: Observacao
A2: 128 | B2: 04/08/2023 | C2: NORDESTE | D2: ACESSÓRIOS | E2: Película Vidro | F2: online | G2: Pessoa Física | H2: Sabrina Castro | I2: 1 | J2: 334.41 | K2: 205.99
A3: 28 | B3: 06/03/2023 | C3: NORDESTE | D3: FONES DE OUVIDO | E3: AirPods 2 | F3: online | G3: Pessoa Física | H3: Rafael Teixeira | I3: 2 | J3: 413.33 | K3: 275.48
A4: 226 | B4: 08/02/2024 | C4: sudeste | D4: tablets | E4: Galaxy Tab A8 | F4: online | G4: Pessoa Física | H4: Patrícia Gomes | I4: 1 | J4: 915.45 | K4: 661.69
A5: 155 | B5: 28/09/2023 | C5: SUDESTE | D5: FONES DE OUVIDO | E5: JBL Tune 510BT | F5: LOJA FÍSICA | G5: Pessoa Jurídica | H5: Sabrina Castro | I5: 1 | J5: 835.27 | K5: 559.35
A6: 143 | B6: 28/08/2023 | C6: Sudeste | D6: Acessórios | E6: Suporte Veicular | F6: LOJA FÍSICA | G6: Pessoa Física | H6: Elaine Rocha | I6: 1 | J6: 290.76 | K6: 178.88
A7: 88 | B7: 13/05/2023 | C7: SUDESTE | D7: FONES DE OUVIDO | E7: Galaxy Buds FE | F7: online | G7: Pessoa Física | H7: João Ferreira | I7: 1 | J7: 583.71 | K7: 374.56
A8: 115 | B8: 14/07/2023 | C8: Nordeste | D8: tablets | E8: iPad 9ª Ger | F8: Loja Física | G8: Pessoa Jurídica | H8: Elaine Rocha | I8: 2 | J8: 955.73 | K8: 549.46
A9: 238 | B9: 22/02/2024 | C9: sudeste | D9: fones de ouvido | E9: Galaxy Buds FE | F9: loja física | G9: Pessoa Física | H9: João Ferreira | I9: 1 | J9: 146.55 | K9: 96.69
A10: 154 | B10: 28/09/2023 | C10: sudeste | D10: Fones de Ouvido | E10: Fone Bluetooth XPTO | F10: LOJA FÍSICA | G10: Pessoa Jurídica | H10: Gabriela Alves | I10: 2 | J10: 424.71 | K10: 307.04
A11: 124 | B11: 30/07/2023 | C11: NORDESTE | D11: FONES DE OUVIDO | E11: AirPods 2 | F11: LOJA FÍSICA | G11: Pessoa Física | H11: Patrícia Gomes | I11: 1 | J11: 583.98 | K11: 404.11
A12: 147 | B12: 01/09/2023 | C12: Sudeste | D12: notebooks | E12: Vivobook 15 | F12: Online | G12: Pessoa Física | H12: Gabriela Alves | I12: 1 | J12: 6317.25 | K12: 3670.71
A13: 292 | B13: 23/05/2024 | C13: NORDESTE | D13: Tablets | E13: iPad 9ª Ger | F13: online | G13: Pessoa Física | H13: Sabrina Castro | I13: 2 | J13: 1230.99 | K13: 704.25
... A24: 269 | B24: 19/04/2024 | C24: SUDESTE | D24: tablets | E24: Lenovo Tab M10 | F24: online | G24: Pessoa Jurídica | H24: Otávio Nunes | I24: 2 | J24: 2895.48 | K24: 2253.31
A25: 16 | B25: 02/02/2023 | C25: norte | D25: acessórios | E25: Suporte Veicular | F25: online | G25: Pessoa Física | H25: João Ferreira | I25: 1 | J25: 199.17
A26: 41 | B26: 19/03/2023 | C26: CENTRO-OESTE | D26: smartphones | E26: Redmi Note 12 | F26: LOJA FÍSICA | G26: Pessoa Física | H26: Bruno Costa | I26: 2 | J26: 2348.44 | K26: 1623.9
A27: 297 | B27: 06/06/2024 | C27: Sudeste | D27: Acessórios | E27: Carregador Turbo | F27: Online | G27: Pessoa Jurídica | H27: Thiago Moreira | I27: 1 | J27: 191.35 | K27: 119.09
A28: 82 | B28: 02/05/2023 | C28: Sudeste | D28: acessórios | E28: Capinha Silicone | F28: loja física | G28: Pessoa Física | H28: Otávio Nunes | I28: 2 | J28: 274.69 | K28: 181.44
A29: 246 | B29: 06/03/2024 | C29: norte | D29: Acessórios | E29: Suporte Veicular | F29: loja física | G29: Pessoa Física | H29: Isabela Martins | I29: 1 | J29: 31.16 | K29: 17.92
A30: 318 | B30: 17/07/2024 | C30: Centro-Oeste | D30: tablets | E30: iPad 9ª Ger | F30: Loja Física | G30: Pessoa Física | H30: Ana Silva | I30: 1 | J30: 1627.63 | K30: 1140.73
A31: 198 | B31: 08/12/2023 | C31: NORDESTE | D31: FONES DE OUVIDO | E31: JBL Tune 510BT | F31: LOJA FÍSICA | G31: Pessoa Física | H31: Sabrina Castro | I31: 1 | J31: 895.91 | K31: 572.02
A32: 256 | B32: 24/03/2024 | C32: Sudeste | D32: Acessórios | E32: Carregador Turbo | F32: loja física | G32: Pessoa Física | H32: Diego Lima | I32: 2 | J32: 337 | K32: 235.03
A33: 81 | B33: 01/05/2023 | C33: CENTRO-OESTE | D33: Tablets | E33: iPad 9ª Ger | F33: Online | G33: Pessoa Física | H33: Isabela Martins | I33: 1 | J33: 1681.35 | K33: 1128.75
A34: 131 | B34: 09/08/2023 | C34: CENTRO-OESTE | D34: Smartphones | E34: iPhone 13 | F34: loja física | G34: Pessoa Física | H34: Patrícia Gomes | I34: 2 | J34: 2863.79 | K34: 1881.16
A35: 104 | B35: 20/06/2023 | C35: Sudeste | D35: FONES DE OUVIDO | E35: Galaxy Buds FE | F35: ONLINE | G35: Pessoa Física | H35: Hugo Pereira | I35: 1 | J35: 835.92 | K35: 599.37
A36: 108 | B36: 25/06/2023 | C36: Sul | D36: Smartphones | E36: iPhone 13 | F36: ONLINE | G36: Pessoa Jurídica | H36: Thiago Moreira | I36: 1 | J36: 4341.37 | K36: 3149.64
A37: 314 | B37: 10/07/2024 | C37: Sudeste | D37: NOTEBOOKS | E37: Inspiron 15 | F37: ONLINE | G37: Pessoa Jurídica | H37: Sabrina Castro | I37: 1 | J37: 7573.14 | K37: 4518.26
A38: 291 | B38: 22/05/2024 | C38: Nordeste | D38: notebooks | E38: Inspiron 15 | F38: Online | G38: Pessoa Física | H38: Mariana Ribeiro | I38: 1 | J38: 5848.44 | K38: 3515.2
A39: 202 | B39: 14/12/2023 | C39: SUDESTE | D39: tablets | E39: iPad 9ª Ger | F39: loja física | G39: Pessoa Jurídica | H39: Carla Souza | I39: 2 | J39: 2401.72
A40: 138 | B40: 18/08/2023 | C40: nordeste | D40: Acessórios | E40: Suporte Veicular | F40: ONLINE | G40: Pessoa Física | H40: Rafael Teixeira | I40: 1 | J40: 195.09 | K40: 130
A41: 189 | B41: 28/11/2023 | C41: NORDESTE | D41: Fones de Ouvido | E41: AirPods 2 | F41: LOJA FÍSICA | G41: Pessoa Física | H41: Nicolas Barros | I41: 2 | J41: 438.44 | K41: 341.75
A42: 102 | B42: 19/06/2023 | C42: norte | D42: SMARTPHONES | E42: iPhone 13 | F42: LOJA FÍSICA | G42: Pessoa Física | H42: Sabrina Castro | I42: 1 | J42: 1313.75 | K42: 1024.54
A43: 242 | B43: 29/02/2024 | C43: sudeste | D43: NOTEBOOKS | E43: MacBook Air M1 | F43: Loja Física | G43: Pessoa Jurídica | H43: Diego Lima | I43: 1 | J43: 5355.42 | K43: 3164.62
A44: 270 | B44: 20/04/2024 | C44: Sudeste | D44: Smartphones | E44: Galaxy A54 | F44: loja física | G44: Pessoa Física | H44: Diego Lima | I44: 1 | J44: 3725.56 | K44: 2820.49
A45: 264 | B45: 10/04/2024 | C45: SUDESTE | D45: ACESSÓRIOS | E45: Película Vidro | F45: ONLINE | G45: Pessoa Jurídica | H45: Karina Dias | I45: 1 | J45: 313.48 | K45: 196.21
A46: 129 | B46: 05/08/2023 | C46: NORDESTE | D46: SMARTPHONES | E46: Galaxy S23 | F46: Online | G46: Pessoa Física | H46: Karina Dias | I46: 1 | J46: 2257.5 | K46: 1539.58
A47: 409 | B47: 03/12/2024 | C47: sudeste | D47: tablets | E47: iPad 9ª Ger | F47: online | G47: Pessoa Física | H47: Hugo Pereira | I47: 1 | J47: 1522.6 | K47: 947.65
A48: 346 | B48: 17/08/2024 | C48: SUL | D48: tablets | E48: Lenovo Tab M10 | F48: ONLINE | G48: Pessoa Jurídica | H48: João Ferreira | I48: 1 | J48: 2354.07 | K48: 1426.96
A49: 105 | B49: 22/06/2023 | C49: Nordeste | D49: Fones de Ouvido | E49: Galaxy Buds FE | F49: Loja Física | G49: Pessoa Física | H49: Patrícia Gomes | I49: 1 | J49: 592.3 | K49: 408.35
A50: 282 | B50: 04/05/2024 | C50: centro-oeste | D50: Tablets | E50: Lenovo Tab M10 | F50: Online | G50: Pessoa Física | H50: João Ferreira | I50: 1 | J50: 2459.27 | K50: 1532.51
...

Sheet Power_Query_ETL
B2: Importação e Tratamento no Power Query
B3: Dados > Obter Dados > De Tabela/Intervalo (fonte: tblBruta) → Editor do Power Query
B5: Etapa | D5: O que faz
B6: 1. Origem | D6: Dados > Obter Dados > De Tabela/Intervalo, selecionando a tabela tblBruta.
B7: 2. Renomear Colunas | D7: Padroniza os nomes: id_venda->ID_Venda, DATA_VENDA->Data, " regiao"->Regiao, "categoria "->Categoria, "CANAL "->Canal, segmento->Segmento_Cliente, "Cliente "->Cliente, QTD->Quantidade, preco_unitario->Preco_Unitario, custo_unitario->Custo_Unitario.
B8: 3. Remover Colunas | D8: Remove a coluna Observacao (não utilizada na análise).
B9: 4. Limpar e Formatar Texto | D9: Text.Trim + Text.Clean + Text.Proper em Regiao, Categoria, Canal, Cliente e Produto — remove espaços duplos/laterais e padroniza a capitalização.
B10: 5. Alterar Tipo | D10: Data -> Data; Quantidade -> Número Inteiro; Preco_Unitario e Custo_Unitario -> Número Decimal.
B11: 6. Remover Duplicatas | D11: Table.Distinct remove as 14 linhas 100% repetidas geradas pelo reenvio do sistema.
B12: 7. Filtrar Linhas | D12: Mantém apenas Quantidade > 0, eliminando os 10 registros com erro de digitação no PDV (0 ou negativos).
B13: 8. Agrupar por Categoria | D13: Table.Group calcula a razão média Custo_Unitario / Preco_Unitario por categoria, usando somente linhas com custo preenchido.
B14: 9. Mesclar Consultas (Merge) | D14: Junta a razão média de volta à base principal pela chave Categoria (Junção Externa Esquerda).
B15: 10. Preencher Valores Ausentes | D15: Substitui os 26 custos nulos por Preco_Unitario x Razão_Média_da_Categoria, e remove a coluna auxiliar.
B16: 11. Colunas Personalizadas | D16: Adiciona Receita (Qtd x Preço), Custo_Total (Qtd x Custo), Lucro (Receita - Custo_Total) e Margem_% (Lucro/Receita).
... B19: 14. Ordenar e Carregar | D19: Ordena por Data crescente e usa Fechar e Carregar Como Tabela na planilha Base_Tratada.
B21: Código M completo (Editor Avançado)
B22: let Origem = Excel.CurrentWorkbook(){[Name="tblBruta"]}[Content], ColunasRenomeadas = Table.RenameColumns(Origem,{{"id_venda","ID_Venda"},{"DATA_VENDA","Data"}, {" regiao","Regiao"},{"categoria ","Categoria"},{"CANAL ","Canal"},{"segmento","Segmento_Cliente"}, {"Cliente ","Cliente"},{"QTD","Quantidade"},{"preco_unitario","Preco_Unitario"},{"custo_unitario","Custo_Unitario"}}), ColunaRemovida = Table.RemoveColumns(ColunasRenomeadas,{"Observacao"}), TextoLimpo = Table.TransformColumns(ColunaRemovida,{ {"Regiao", each Text.Proper(Text.Trim(Text.Clean(_))), type text}, {"Categoria", each Text.Proper(Text.Trim(Text.Clean(_))), type text}, {"Canal", each Text.Proper(Text.Trim(Text.Clean(_))), type text}, {"Cliente", each Text.Proper(Text.Trim(Text.Clean(_))), type text}, {"Produto", each Text.Trim(Text.Clean(_)), type text}}), TiposCorrigidos = Table.TransformColumnTypes(TextoLimpo,{{"Data", type date}, {"Quantidade", Int64.Type}, {"Preco_Unitario", type number}, {"Custo_Unitario", type number}}), SemDuplicatas = Table.Distinct(TiposCorrigidos), LinhasFiltradas = Table.SelectRows(SemDuplicatas, each [Quantidade] > 0), MediaPorCategoria = Table.Group( Table.SelectRows(LinhasFiltradas, each [Custo_Unitario] <> null), {"Categoria"}, {{"Razao_Media", each List.Average(List.Transform(_, (r) => r[Custo_Unitario] / r[Preco_Unitario])), type number}}), BaseComRazao = Table.NestedJoin(LinhasFiltradas, {"Categoria"}, MediaPorCategoria, {"Categoria"}, "Ref", JoinKind.LeftOuter), BaseExpandida = Table.ExpandTableColumn(BaseComRazao, "Ref", {"Razao_Media"}), CustoPreenchido = Table.ReplaceValue(BaseExpandida, each [Custo_Unitario], each if [Custo_Unitario] = null then Number.Round([Preco_Unitario] * [Razao_Media], 2) else [Custo_Unitario], Replacer.ReplaceValue, {"Custo_Unitario"}), SemColunaAuxiliar = Table.RemoveColumns(CustoPreenchido, {"Razao_Media"}), ColReceita = Table.AddColumn(SemColunaAuxiliar, "Receita", each [Quantidade] * [Preco_Unitario], type number), ColCustoTotal = Table.AddColumn(ColReceita, "Custo_Total", each [Quantidade] * [Custo_Unitario], type number), ColLucro = Table.AddColumn(ColCustoTotal, "Lucro", each [Receita] - [Custo_Total], type number), ColMargem = Table.AddColumn(ColLucro, "Margem_%", each [Lucro] / [Receita], type number), ColFaixa = Table.AddColumn(ColMargem, "Faixa_Receita", each if [Receita] >= 3000 then "Alta" else if [Receita] >= 1000 then "Média" else "Baixa", type text), ColAno = Table.AddColumn(ColFaixa, "Ano", each Date.Year([Data]), Int64.Type), ColMes = Table.AddColumn(ColAno, "Mes", each Date.Month([Data]), Int64.Type), OrdenadoPorData = Table.Sort(ColMes,{{"Data", Order.Ascending}}) in OrdenadoPorData

Sheet Base_Tratada
A1: ID_Venda | B1: Data | C1: Ano | D1: Mes | E1: Regiao | F1: Categoria | G1: Produto | H1: Canal | I1: Segmento_Cliente | J1: Cliente | K1: Quantidade | L1: Preco_Unitario | M1: Custo_Unitario | N1: Receita | O1: Custo_Total | P1: Lucro | Q1: Margem_% | R1: Faixa_Receita
A2: 1 | B2: 44932 | C2: 2023 | D2: 1 | E2: Sudeste | F2: Acessórios | G2: Suporte Veicular | H2: Online | I2: Pessoa Física | J2: Fábio Santos | K2: 1 | L2: 225.45 | M2: 144.54 | N2: 225.45 | O2: 144.54 | P2: 80.91 | Q2: 0.3589 | R2: Baixa
A3: 2 | B3: 44935 | C3: 2023 | D3: 1 | E3: Nordeste | F3: Notebooks | G3: Thinkpad E14 | H3: Online | I3: Pessoa Física | J3: Isabela Martins | K3: 1 | L3: 4272.76 | M3: 3155.96 | N3: 4272.76 | O3: 3155.96 | P3: 1116.8 | Q3: 0.2614 | R3: Alta
A4: 3 | B4: 44937 | C4: 2023 | D4: 1 | E4: Sudeste | F4: Tablets | G4: Ipad 9ª Ger | H4: Loja Física | I4: Pessoa Física | J4: Rafael Teixeira | K4: 1 | L4: 1644.97 | M4: 1274.77 | N4: 1644.97 | O4: 1274.77 | P4: 370.2 | Q4: 0.225 | R4: Média
A5: 4 | B5: 44940 | C5: 2023 | D5: 1 | E5: Sudeste | F5: Smartphones | G5: Iphone 13 | H5: Online | I5: Pessoa Física | J5: Vanessa Cardoso | K5: 1 | L5: 1889.57 | M5: 1288.57 | N5: 1889.57 | O5: 1288.57 | P5: 601 | Q5: 0.3181 | R5: Média
A6: 5 | B6: 44942 | C6: 2023 | D6: 1 | E6: Sudeste | F6: Fones de Ouvido | G6: Jbl Tune 510Bt | H6: Online | I6: Pessoa Física | J6: Hugo Pereira | K6: 1 | L6: 764.8 | M6: 421.4 | N6: 764.8 | O6: 421.4 | P6: 343.4 | Q6: 0.449 | R6: Baixa
A7: 6 | B7: 44942 | C7: 2023 | D7: 1 | E7: Sul | F7: Fones de Ouvido | G7: Galaxy Buds Fe | H7: Loja Física | I7: Pessoa Jurídica | J7: Rafael Teixeira | K7: 1 | L7: 527.07 | M7: 374.35 | N7: 527.07 | O7: 374.35 | P7: 152.72 | Q7: 0.2898 | R7: Baixa
A8: 7 | B8: 44943 | C8: 2023 | D8: 1 | E8: Sudeste | F8: Fones de Ouvido | G8: Fone Bluetooth Xpto | H8: Online | I8: Pessoa Física | J8: Vanessa Cardoso | K8: 1 | L8: 384.15 | M8: 283.04 | N8: 384.15 | O8: 283.04 | P8: 101.11 | Q8: 0.2632 | R8: Baixa
A9: 8 | B9: 44943 | C9: 2023 | D9: 1 | E9: Sul | F9: Notebooks | G9: Ideapad 3 | H9: Online | I9: Pessoa Física | J9: Fábio Santos | K9: 1 | L9: 5722.79 | M9: 3435.6 | N9: 5722.79 | O9: 3435.6 | P9: 2287.19 | Q9: 0.3997 | R9: Alta
A10: 9 | B10: 44945 | C10: 2023 | D10: 1 | E10: Sul | F10: Smartphones | G10: Galaxy A54 | H10: Online | I10: Pessoa Jurídica | J10: Nicolas Barros | K10: 1 | L10: 2318.75 | M10: 1325.46 | N10: 2318.75 | O10: 1325.46 | P10: 993.29 | Q10: 0.4284 | R10: Média
A11: 10 | B11: 44948 | C11: 2023 | D11: 1 | E11: Sudeste | F11: Fones de Ouvido | G11: Jbl Tune 510Bt | H11: Online | I11: Pessoa Física | J11: Lucas Oliveira | K11: 3 | L11: 217.18 | M11: 132.19 | N11: 651.54 | O11: 396.57 | P11: 254.97 | Q11: 0.3913 | R11: Baixa
A12: 11 | B12: 44949 | C12: 2023 | D12: 1 | E12: Nordeste | F12: Acessórios | G12: Capinha Silicone | H12: Loja Física | I12: Pessoa Física | J12: João Ferreira | K12: 1 | L12: 335.03 | M12: 226.99 | N12: 335.03 | O12: 226.99 | P12: 108.04 | Q12: 0.3225 | R12: Baixa
A13: 12 | B13: 44954 | C13: 2023 | D13: 1 | E13: Centro-Oeste | F13: Tablets | G13: Galaxy Tab A8 | H13: Online | I13: Pessoa Física | J13: Bruno Costa | K13: 2 | L13: 1701.03 | M13: 947.65 | N13: 3402.06 | O13: 1895.3 | P13: 1506.76 | Q13: 0.4429 | R13: Alta
... A412: 411 | B412: 45656 | C412: 2024 | D412: 12 | E412: Norte | F412: Smartphones | G412: Redmi Note 12 | H412: Loja Física | I412: Pessoa Física | J412: Karina Dias | K412: 1 | L412: 3681.44 | M412: 2278.31 | N412: 3681.44 | O412: 2278.31 | P412: 1403.13 | Q412: 0.3811 | R412: Alta

Sheet Medidas_Indicadores
B2: Indicadores construídos a partir de Medidas
B4: Medida | D4: Valor
B5: Medida_ReceitaTotal | D5: =SUM(Base_Tratada!N:N) -> 1015597.6
B6: Medida_LucroTotal | D6: =SUM(Base_Tratada!P:P) -> 340779.86
B7: Medida_MargemMedia | D7: =AVERAGE(Base_Tratada!Q:Q) -> 0.33411849
B8: Medida_TotalPedidos | D8: =COUNT(Base_Tratada!A:A) -> 411
B9: Medida_TicketMedio | D9: =D5/D8 -> 2471.0404
B10: Medida_QtdTotal | D10: =SUM(Base_Tratada!K:K) -> 513
B13: Consulta Avançada — Múltiplos Critérios
B14: Categoria: | D14: Acessórios
B15: Canal: | D15: Loja Física
B16: Ano: | D16: 2023
B17: Resultado | D17: Valor
B18: Receita (3 critérios) | D18: =SUMIFS(Base_Tratada!N:N,Base_Tratada!F:F,D14,Base_Tratada!H:H,D15,Base_Tratada!C:C,D16) -> 4435.05
B19: Lucro (3 critérios) | D19: =SUMIFS(Base_Tratada!P:P,Base_Tratada!F:F,D14,Base_Tratada!H:H,D15,Base_Tratada!C:C,D16) -> 1654.19
B20: Nº de Pedidos (3 critérios) | D20: =COUNTIFS(Base_Tratada!F:F,D14,Base_Tratada!H:H,D15,Base_Tratada!C:C,D16) -> 17
B21: Cliente da maior venda (2 critérios) | D21: =IFERROR(INDEX(Base_Tratada!J2:J412,MATCH(SUMPRODUCT(MAX((Base_Tratada!F2:F412=D14)*(Base_Tratada!H2:H412=D15)*Base_Tratada!N2:N412)),Base_Tratada!N2:N412,0)),"—") -> Lucas Oliveira

Sheet Tabela_Dinamica
B2: Tabela Dinâmica Estruturada — Receita por Categoria x Canal
B3: Construída com SUMIFS de múltiplos critérios sobre Base_Tratada (atualiza automaticamente).
B6: Categoria \ Canal | C6: Loja Física | D6: Online | E6: Total Geral
B7: Acessórios | C7: =SUMIFS(Base_Tratada!N:N,Base_Tratada!F:F,$B7,Base_Tratada!H:H,C$6) -> 8587.35 | D7: =SUMIFS(Base_Tratada!N:N,Base_Tratada!F:F,$B7,Base_Tratada!H:H,D$6) -> 11548.6 | E7: =SUM(C7:D7) -> 20135.95
B8: Fones de Ouvido | C8: =SUMIFS(Base_Tratada!N:N,Base_Tratada!F:F,$B8,Base_Tratada!H:H,C$6) -> 30686.34 | D8: =SUMIFS(Base_Tratada!N:N,Base_Tratada!F:F,$B8,Base_Tratada!H:H,D$6) -> 30094.48 | E8: =SUM(C8:D8) -> 60780.82
B9: Notebooks | C9: =SUMIFS(Base_Tratada!N:N,Base_Tratada!F:F,$B9,Base_Tratada!H:H,C$6) -> 73801.71 | D9: =SUMIFS(Base_Tratada!N:N,Base_Tratada!F:F,$B9,Base_Tratada!H:H,D$6) -> 247270.2 | E9: =SUM(C9:D9) -> 321071.91
B10: Smartphones | C10: =SUMIFS(Base_Tratada!N:N,Base_Tratada!F:F,$B10,Base_Tratada!H:H,C$6) -> 243969.81 | D10: =SUMIFS(Base_Tratada!N:N,Base_Tratada!F:F,$B10,Base_Tratada!H:H,D$6) -> 224705.56 | E10: =SUM(C10:D10) -> 468675.37
B11: Tablets | C11: =SUMIFS(Base_Tratada!N:N,Base_Tratada!F:F,$B11,Base_Tratada!H:H,C$6) -> 72096.51 | D11: =SUMIFS(Base_Tratada!N:N,Base_Tratada!F:F,$B11,Base_Tratada!H:H,D$6) -> 72837.05 | E11: =SUM(C11:D11) -> 144933.56
B12: Total Geral | C12: =SUM(C7:C11) -> 429141.72 | D12: =SUM(D7:D11) -> 586455.89 | E12: =SUM(E7:E11) -> 1015597.6
B15: Nº de Pedidos por Região x Faixa de Receita
B16: Região \ Faixa | C16: Baixa | D16: Média | E16: Alta
B17: Centro-Oeste | C17: =COUNTIFS(Base_Tratada!E:E,$B17,Base_Tratada!R:R,C$16) -> 15 | D17: =COUNTIFS(Base_Tratada!E:E,$B17,Base_Tratada!R:R,D$16) -> 13 | E17: =COUNTIFS(Base_Tratada!E:E,$B17,Base_Tratada!R:R,E$16) -> 18
B18: Nordeste | C18: =COUNTIFS(Base_Tratada!E:E,$B18,Base_Tratada!R:R,C$16) -> 27 | D18: =COUNTIFS(Base_Tratada!E:E,$B18,Base_Tratada!R:R,D$16) -> 14 | E18: =COUNTIFS(Base_Tratada!E:E,$B18,Base_Tratada!R:R,E$16) -> 25
B19: Norte | C19: =COUNTIFS(Base_Tratada!E:E,$B19,Base_Tratada!R:R,C$16) -> 17 | D19: =COUNTIFS(Base_Tratada!E:E,$B19,Base_Tratada!R:R,D$16) -> 14 | E19: =COUNTIFS(Base_Tratada!E:E,$B19,Base_Tratada!R:R,E$16) -> 13
B20: Sudeste | C20: =COUNTIFS(Base_Tratada!E:E,$B20,Base_Tratada!R:R,C$16) -> 79 | D20: =COUNTIFS(Base_Tratada!E:E,$B20,Base_Tratada!R:R,D$16) -> 40 | E20: =COUNTIFS(Base_Tratada!E:E,$B20,Base_Tratada!R:R,E$16) -> 56
B21: Sul | C21: =COUNTIFS(Base_Tratada!E:E,$B21,Base_Tratada!R:R,C$16) -> 34 | D21: =COUNTIFS(Base_Tratada!E:E,$B21,Base_Tratada!R:R,D$16) -> 21 | E21: =COUNTIFS(Base_Tratada!E:E,$B21,Base_Tratada!R:R,E$16) -> 25
B59: Tabela auxiliar — Receita por mês (fonte do gráfico de tendência)
B60: AnoMes | C60: Receita
B61: 2023-01 | C61: =SUMIFS(Base_Tratada!N:N,Base_Tratada!C:C,2023,Base_Tratada!D:D,1) -> 22280.18
B62: 2023-02 | C62: =SUMIFS(Base_Tratada!N:N,Base_Tratada!C:C,2023,Base_Tratada!D:D,2) -> 25651.81
B63: 2023-03 | C63: =SUMIFS(Base_Tratada!N:N,Base_Tratada!C:C,2023,Base_Tratada!D:D,3) -> 75293.56
B64: 2023-04 | C64: =SUMIFS(Base_Tratada!N:N,Base_Tratada!C:C,2023,Base_Tratada!D:D,4) -> 70785.13
B65: 2023-05 | C65: =SUMIFS(Base_Tratada!N:N,Base_Tratada!C:C,2023,Base_Tratada!D:D,5) -> 31612.36
B66: 2023-06 | C66: =SUMIFS(Base_Tratada!N:N,Base_Tratada!C:C,2023,Base_Tratada!D:D,6) -> 33521.97
B67: 2023-07 | C67: =SUMIFS(Base_Tratada!N:N,Base_Tratada!C:C,2023,Base_Tratada!D:D,7) -> 29480.17
B68: 2023-08 | C68: =SUMIFS(Base_Tratada!N:N,Base_Tratada!C:C,2023,Base_Tratada!D:D,8) -> 40435.57
B69: 2023-09 | C69: =SUMIFS(Base_Tratada!N:N,Base_Tratada!C:C,2023,Base_Tratada!D:D,9) -> 22605.33
B70: 2023-10 | C70: =SUMIFS(Base_Tratada!N:N,Base_Tratada!C:C,2023,Base_Tratada!D:D,10) -> 30046.72
B71: 2023-11 | C71: =SUMIFS(Base_Tratada!N:N,Base_Tratada!C:C,2023,Base_Tratada!D:D,11) -> 50154.31
B72: 2023-12 | C72: =SUMIFS(Base_Tratada!N:N,Base_Tratada!C:C,2023,Base_Tratada!D:D,12) -> 70724.14
B73: 2024-01 | C73: =SUMIFS(Base_Tratada!N:N,Base_Tratada!C:C,2024,Base_Tratada!D:D,1) -> 26891.71
B74: 2024-02 | C74: =SUMIFS(Base_Tratada!N:N,Base_Tratada!C:C,2024,Base_Tratada!D:D,2) -> 39853.66
B75: 2024-03 | C75: =SUMIFS(Base_Tratada!N:N,Base_Tratada!C:C,2024,Base_Tratada!D:D,3) -> 39096.75
B76: 2024-04 | C76: =SUMIFS(Base_Tratada!N:N,Base_Tratada!C:C,2024,Base_Tratada!D:D,4) -> 62074.87
B77: 2024-05 | C77: =SUMIFS(Base_Tratada!N:N,Base_Tratada!C:C,2024,Base_Tratada!D:D,5) -> 39454.9
B78: 2024-06 | C78: =SUMIFS(Base_Tratada!N:N,Base_Tratada!C:C,2024,Base_Tratada!D:D,6) -> 37682.44
B79: 2024-07 | C79: =SUMIFS(Base_Tratada!N:N,Base_Tratada!C:C,2024,Base_Tratada!D:D,7) -> 68097.81
B80: 2024-08 | C80: =SUMIFS(Base_Tratada!N:N,Base_Tratada!C:C,2024,Base_Tratada!D:D,8) -> 61396.74
B81: 2024-09 | C81: =SUMIFS(Base_Tratada!N:N,Base_Tratada!C:C,2024,Base_Tratada!D:D,9) -> 39152.21
B82: 2024-10 | C82: =SUMIFS(Base_Tratada!N:N,Base_Tratada!C:C,2024,Base_Tratada!D:D,10) -> 25629.95
...

Sheet Dashboard
B2: Mini Dashboard Analítico — Vendas de Eletrônicos
B4: Receita Total | E4: Lucro Total | H4: Margem Média | K4: Ticket Médio
B5: =Medida_ReceitaTotal -> 1015597.6 | E5: =Medida_LucroTotal -> 340779.86 | H5: =Medida_MargemMedia -> 0.33411849 | K5: =Medida_TicketMedio -> 2471.0404
